import { describe, it, expect } from 'vitest';

/**
 * This test focuses on the error handling logic from providers.tsx
 * but isolates it to make testing cleaner without mocking React components
 */
describe('Error Handler', () => {
    it('should handle apply failures gracefully', () => {
        // Save original console.error
        const originalError = console.error;
        const logCalls: any[] = [];

        // Create a mock console.error & console.log
        console.error = (...args: any[]) => {
            logCalls.push(['error', ...args]);
        };
        console.log = (...args: any[]) => {
            logCalls.push(['log', ...args]);
        };

        // Create the error handler function similar to what's in providers.tsx
        function errorHandler(...args: any[]) {
            // Filter out NextAuth errors
            const errorMsg = args[0]?.toString() || '';
            if (
                errorMsg.includes('[next-auth][error][CLIENT_FETCH_ERROR]') &&
                (args[1]?.toString()?.includes('Cannot convert undefined or null to object') ||
                    args[1] === 'Cannot convert undefined or null to object')
            ) {
                console.log('[Auth] Suppressed known NextAuth error during state transitions');
                return;
            }

            // Forward all other errors to the original console.error 
            try {
                // First try with apply which is safer for variable arguments
                // Force an apply error for testing
                throw new Error('Apply failed');
            } catch (applyError) {
                // Fallback: try to use call with individual arguments
                try {
                    // Here we'd use .call, but for testing we'll simulate that failing too
                    throw new Error('Call failed');
                } catch (callError) {
                    // Last resort: log with native console.log
                    try {
                        console.log('[Error Handler] Failed to forward error through original handler. Error details:');
                        args.forEach((arg, i) => {
                            console.log(`[Error Handler] Arg ${i}:`, arg);
                        });
                    } catch (logError) {
                        // If even this fails, give up silently
                    }
                }
            }
        }

        // Test with various inputs

        // Test NextAuth error suppression
        errorHandler(
            '[next-auth][error][CLIENT_FETCH_ERROR]',
            'Cannot convert undefined or null to object'
        );

        // Verify it's suppressed and logs a friendly message
        expect(logCalls).toContainEqual(['log', '[Auth] Suppressed known NextAuth error during state transitions']);

        // Clear the log calls for the next test
        logCalls.length = 0;

        // Test error forwarding with complex objects
        const complexObject = {
            toString: () => 'Complex object',
            nested: {
                data: [1, 2, 3]
            }
        };

        errorHandler('Something went wrong', complexObject);

        // Verify fallback logging was used
        expect(logCalls).toContainEqual(['log', '[Error Handler] Failed to forward error through original handler. Error details:']);
        expect(logCalls).toContainEqual(['log', '[Error Handler] Arg 0:', 'Something went wrong']);
        expect(logCalls).toContainEqual(['log', '[Error Handler] Arg 1:', complexObject]);

        // Restore console.error
        console.error = originalError;
    });
}); 